Traceback (most recent call last):
  File "c:\Users\Jesli's Laptop\AppData\Local\Programs\Python\Python39\lib\site-packages\wandb\sdk\wandb_config.py", line 162, in __getattr__
    return self.__getitem__(key)
  File "c:\Users\Jesli's Laptop\AppData\Local\Programs\Python\Python39\lib\site-packages\wandb\sdk\wandb_config.py", line 130, in __getitem__
    return self._items[key]
KeyError: 'embedding_dim'
The above exception was the direct cause of the following exception:
Traceback (most recent call last):
  File "C:\Users\Jesli's Laptop\AppData\Local\Temp\ipykernel_31044\2923158279.py", line 11, in hyperparam_search
    embedding_dim = config.embedding_dim
  File "c:\Users\Jesli's Laptop\AppData\Local\Programs\Python\Python39\lib\site-packages\wandb\sdk\wandb_config.py", line 164, in __getattr__
    raise AttributeError(
AttributeError: <class 'wandb.sdk.wandb_config.Config'> object has no attribute 'embedding_dim'